Traceback (most recent call last):
  File "C:\Users\GLENDY\AppData\Local\Programs\Python\Python311\Lib\site-packages\jupyter_cache\executors\utils.py", line 58, in single_nb_execution
    executenb(
  File "C:\Users\GLENDY\AppData\Local\Programs\Python\Python311\Lib\site-packages\nbclient\client.py", line 1314, in execute
    return NotebookClient(nb=nb, resources=resources, km=km, **kwargs).execute()
           ^^^^^^^^^^^^^^^^^^^^^^^^^^^^^^^^^^^^^^^^^^^^^^^^^^^^^^^^^^^^^^^^^^^^^
  File "C:\Users\GLENDY\AppData\Roaming\Python\Python311\site-packages\jupyter_core\utils\__init__.py", line 173, in wrapped
    return loop.run_until_complete(inner)
           ^^^^^^^^^^^^^^^^^^^^^^^^^^^^^^
  File "C:\Users\GLENDY\AppData\Local\Programs\Python\Python311\Lib\asyncio\base_events.py", line 653, in run_until_complete
    return future.result()
           ^^^^^^^^^^^^^^^
  File "C:\Users\GLENDY\AppData\Local\Programs\Python\Python311\Lib\site-packages\nbclient\client.py", line 709, in async_execute
    await self.async_execute_cell(
  File "C:\Users\GLENDY\AppData\Local\Programs\Python\Python311\Lib\site-packages\nbclient\client.py", line 1062, in async_execute_cell
    await self._check_raise_for_error(cell, cell_index, exec_reply)
  File "C:\Users\GLENDY\AppData\Local\Programs\Python\Python311\Lib\site-packages\nbclient\client.py", line 918, in _check_raise_for_error
    raise CellExecutionError.from_cell_and_msg(cell, exec_reply_content)
nbclient.exceptions.CellExecutionError: An error occurred while executing the following cell:
------------------
df_4 = _deepnote_execute_sql('ALTER TABLE "irisSepal"\nDROP COLUMN "PetalLengthCm",\nDROP COLUMN "PetalWidthCm",\nDROP COLUMN "Species";', 'SQL_9F077E84_7AEF_47B3_8C40_E916DA5FA711', audit_sql_comment='', sql_cache_mode='cache_disabled')
df_4
------------------


[1;31m---------------------------------------------------------------------------[0m
[1;31mNameError[0m                                 Traceback (most recent call last)
Cell [1;32mIn[1], line 1[0m
[1;32m----> 1[0m df_4 [38;5;241m=[39m [43m_deepnote_execute_sql[49m([38;5;124m'[39m[38;5;124mALTER TABLE [39m[38;5;124m"[39m[38;5;124mirisSepal[39m[38;5;124m"[39m[38;5;130;01m\n[39;00m[38;5;124mDROP COLUMN [39m[38;5;124m"[39m[38;5;124mPetalLengthCm[39m[38;5;124m"[39m[38;5;124m,[39m[38;5;130;01m\n[39;00m[38;5;124mDROP COLUMN [39m[38;5;124m"[39m[38;5;124mPetalWidthCm[39m[38;5;124m"[39m[38;5;124m,[39m[38;5;130;01m\n[39;00m[38;5;124mDROP COLUMN [39m[38;5;124m"[39m[38;5;124mSpecies[39m[38;5;124m"[39m[38;5;124m;[39m[38;5;124m'[39m, [38;5;124m'[39m[38;5;124mSQL_9F077E84_7AEF_47B3_8C40_E916DA5FA711[39m[38;5;124m'[39m, audit_sql_comment[38;5;241m=[39m[38;5;124m'[39m[38;5;124m'[39m, sql_cache_mode[38;5;241m=[39m[38;5;124m'[39m[38;5;124mcache_disabled[39m[38;5;124m'[39m)
[0;32m      2[0m df_4

[1;31mNameError[0m: name '_deepnote_execute_sql' is not defined

